Workbook
Name holidays: Holidays!$A$2:$A$500

Sheet Actual Revenue
A1: Year | B1: Revenue Code | C1: Description | D1: January | E1: February | F1: March | G1: April | H1: May | I1: June | J1: July | K1: August | L1: September | M1: October | N1: November | O1: December | P1: Total | S1: Instructions
A2: 2020 | B2: 1001.01.00 | C2: =_xlfn.XLOOKUP(B2, 'Revenue Codes'!$A$2:$A$99, 'Revenue Codes'!$B$2:$B$99, "") -> Import Duty | D2: 8.5698624e+09 | E2: 8.1488102e+09 | F2: 5.1729912e+09 | G2: 9.3749773e+09 | H2: 6.0418605e+09 | I2: 1.0288255e+10 | J2: 1.282454e+10 | K2: 1.2749402e+10 | L2: 1.1761995e+10 | M2: 12264343587 | N2: 7066693261 | O2: 9165036084 | P2: =SUM(D2:O2) -> 1.1342877e+11 | S2: 1) Revenue Code description appears automatically when code is entered. If code does not appear, add a new Revenue Code in the relevant Excel Sheet. 2) Fields automatically turns red if negative values are entered. Check and verify if those values are correct. 3) Enter all values in exact figures LKR (Not is millions, '000, billion etc.) 4) Values entered in this shared Excel automatically updates the Revenue Dashboard. If any errors in the dashboard is noticed, check values in this Excel Sheet.
A3: 2020 | B3: 1001.02.00 | C3: =_xlfn.XLOOKUP(B3, 'Revenue Codes'!$A$2:$A$99, 'Revenue Codes'!$B$2:$B$99, "") -> Export Duty | D3: 8894271 | E3: 87156406 | F3: 4115423 | G3: 1706001 | H3: 82998001 | I3: -138833998 | J3: 25531227 | K3: 3535255 | L3: 3505754 | M3: 4284650 | N3: 794437 | O3: 96015303 | P3: =SUM(D3:O3) -> 179702730
A4: 2020 | B4: 1001.04.00 | C4: =_xlfn.XLOOKUP(B4, 'Revenue Codes'!$A$2:$A$99, 'Revenue Codes'!$B$2:$B$99, "") -> PAL | D4: 11977905682 | E4: 11303190126 | F4: 6371475697 | G4: 7512095455 | H4: 6951258425 | I4: 8473303494 | J4: 9856600239 | K4: 9323097028 | L4: 11113490909 | M4: 9962682984 | N4: 10496612878 | O4: 12100297636 | P4: =SUM(D4:O4) -> 115442010553
A5: 2020 | B5: 1001.05.01 | C5: =_xlfn.XLOOKUP(B5, 'Revenue Codes'!$A$2:$A$99, 'Revenue Codes'!$B$2:$B$99, "") -> Cess (Import) | D5: 5113629670 | E5: 4282966641 | F5: 7700543 | G5: 2778891471 | H5: 23941893 | I5: 9495722328 | J5: 5245838886 | K5: 2958589037 | L5: 3906326327 | M5: 3786699039 | N5: 4211884531 | O5: 5482934475 | P5: =SUM(D5:O5) -> 47295124841
A6: 2020 | B6: 1001.05.02 | C6: =_xlfn.XLOOKUP(B6, 'Revenue Codes'!$A$2:$A$99, 'Revenue Codes'!$B$2:$B$99, "") -> Cess (Export) | D6: 194168144 | E6: 92704118 | F6: 135204071 | G6: 87177765 | H6: 93382308 | I6: 344202277 | J6: 201787371 | K6: 230506868 | L6: 193032472 | M6: 117640702 | N6: 4833073 | O6: 235979290 | P6: =SUM(D6:O6) -> 1930618459
A7: 2020 | B7: 1001.06.00 | C7: =_xlfn.XLOOKUP(B7, 'Revenue Codes'!$A$2:$A$99, 'Revenue Codes'!$B$2:$B$99, "") -> Motor Vehicle (Conc.) Levy | D7: 3964401 | E7: 204088 | F7: 3899753 | I7: 1743025 | J7: -9811267 | K7: -2161500 | L7: 2161500 | N7: 313387 | O7: 2167363 | P7: =SUM(D7:O7) -> 2480750
A8: 2020 | B8: 1001.08.00 | C8: =_xlfn.XLOOKUP(B8, 'Revenue Codes'!$A$2:$A$99, 'Revenue Codes'!$B$2:$B$99, "") -> SCL | D8: 6153276217 | E8: 7294943259 | F8: 5818567445 | G8: 4825369566 | H8: 5172522400 | I8: 6894182726 | J8: 10305499874 | K8: 8677060214 | L8: 10419136367 | M8: 7499205343 | N8: 3917141784 | O8: 5732047773 | P8: =SUM(D8:O8) -> 82708952968
A9: 2020 | B9: 1003.01.00 | C9: =_xlfn.XLOOKUP(B9, 'Revenue Codes'!$A$2:$A$99, 'Revenue Codes'!$B$2:$B$99, "") -> LXT | D9: 61026434 | E9: 124797947 | F9: 57493116 | G9: 248458011 | H9: 332450594 | I9: 72154212 | J9: 47859220 | K9: 46135522 | L9: 2168716 | M9: 1576799 | N9: 316665 | O9: 45630 | P9: =SUM(D9:O9) -> 994482866
A10: 2020 | B10: 1002.01.04 | C10: =_xlfn.XLOOKUP(B10, 'Revenue Codes'!$A$2:$A$99, 'Revenue Codes'!$B$2:$B$99, "") -> VAT | D10: 9454699025 | E10: 7367278740 | F10: 6018829396 | G10: 6052997708 | H10: 5008431637 | I10: 4805787671 | J10: 6845220858 | K10: 6072915421 | L10: 8849874653 | M10: 8292903439 | N10: 7549846915 | O10: 9405505341 | P10: =SUM(D10:O10) -> 85724290804
A11: 2020 | B11: 1002.05.00 | C11: =_xlfn.XLOOKUP(B11, 'Revenue Codes'!$A$2:$A$99, 'Revenue Codes'!$B$2:$B$99, "") -> Excise (Spec. Prov.) Levy | L11: 1514969592 | M11: 954272875 | N11: 690098340 | O11: 679609534 | P11: =SUM(D11:O11) -> 3838950341
A12: 2020 | B12: 1002.05.01 | C12: =_xlfn.XLOOKUP(B12, 'Revenue Codes'!$A$2:$A$99, 'Revenue Codes'!$B$2:$B$99, "") -> Cigarette | D12: 8045498721 | E12: 9011085300 | F12: 10824314847 | G12: 5986363600 | H12: 7085634316 | I12: 2490105353 | J12: 4840166084 | K12: 10665599200 | L12: 7128381110 | M12: 12471212300 | N12: 8199679800 | O12: 7596503488 | P12: =SUM(D12:O12) -> 94344544119
A13: 2020 | B13: 1002.05.02 | C13: =_xlfn.XLOOKUP(B13, 'Revenue Codes'!$A$2:$A$99, 'Revenue Codes'!$B$2:$B$99, "") -> Liquor | P13: =SUM(D13:O13) -> 0
A14: 2020 | B14: 1002.05.03 | C14: =_xlfn.XLOOKUP(B14, 'Revenue Codes'!$A$2:$A$99, 'Revenue Codes'!$B$2:$B$99, "") -> Petroleum Products | D14: 5796298360 | E14: 8485608221 | F14: 3983643368 | G14: 4248738760 | H14: 2221808479 | I14: 978475238 | J14: 5476079573 | K14: 6143902143 | L14: 4227546817 | M14: 4786810483 | N14: 2788137661 | O14: 119628690 | P14: =SUM(D14:O14) -> 49256677793
A15: 2020 | B15: 1002.05.04 | C15: =_xlfn.XLOOKUP(B15, 'Revenue Codes'!$A$2:$A$99, 'Revenue Codes'!$B$2:$B$99, "") -> Motor Vehicles | D15: 9705892406 | E15: 7335669722 | F15: 7647544424 | G15: 8861560505 | H15: 6477763234 | I15: 1557808849 | J15: 1130608878 | K15: 434254743 | L15: 773077434 | M15: 650652395 | N15: 736657377 | O15: 3448448031 | P15: =SUM(D15:O15) -> 48759937998
A16: 2020 | B16: 1002.05.99 | C16: =_xlfn.XLOOKUP(B16, 'Revenue Codes'!$A$2:$A$99, 'Revenue Codes'!$B$2:$B$99, "") -> Excise (Other) | D16: 476496458 | E16: 447968821 | F16: 114812890 | G16: 841123556 | H16: 148484499 | I16: 91434270 | J16: 497429318 | K16: 227866926 | L16: 400427620 | M16: 925363497 | N16: 81498791 | O16: 474041585 | P16: =SUM(D16:O16) -> 4726948231
A17: 2020 | B17: 1002.12.03 | C17: =_xlfn.XLOOKUP(B17, 'Revenue Codes'!$A$2:$A$99, 'Revenue Codes'!$B$2:$B$99, "") -> NBT | D17: 6656026 | E17: 6198356 | F17: 495552235 | G17: 37092 | H17: 576788 | I17: 5010774 | J17: 10002490 | K17: 302341 | L17: 478048 | M17: 10426620 | N17: 174245 | O17: 771653382 | P17: =SUM(D17:O17) -> 1307068397
A18: 2020 | B18: 1003.06.00 | C18: =_xlfn.XLOOKUP(B18, 'Revenue Codes'!$A$2:$A$99, 'Revenue Codes'!$B$2:$B$99, "") -> ECL | P18: =SUM(D18:O18) -> 0
A19: 2020 | B19: 1003.07.10 | C19: =_xlfn.XLOOKUP(B19, 'Revenue Codes'!$A$2:$A$99, 'Revenue Codes'!$B$2:$B$99, "") -> VEL | D19: 100576000 | E19: 85712548 | F19: 77366350 | G19: 93839000 | H19: 59849000 | I19: 17097000 | J19: 9056994 | K19: 242560456 | L19: 5270000 | M19: 4264200 | N19: 5872880 | O19: 6057426 | P19: =SUM(D19:O19) -> 707521854
A20: 2020 | B20: 1004.04.02 | C20: =_xlfn.XLOOKUP(B20, 'Revenue Codes'!$A$2:$A$99, 'Revenue Codes'!$B$2:$B$99, "") -> ESC | D20: 18599252 | E20: 107896 | F20: 15900 | H20: 5500 | I20: 9155047 | J20: 11474222 | K20: 6495 | L20: 14790 | M20: 65763763 | N20: -64933066 | O20: 2238274 | P20: =SUM(D20:O20) -> 42448073
A21: 2020 | B21: 2003.02.17 | C21: =_xlfn.XLOOKUP(B21, 'Revenue Codes'!$A$2:$A$99, 'Revenue Codes'!$B$2:$B$99, "") -> Sales of Garment | D21: 7116576 | E21: 20765500 | F21: 16273600 | G21: 900 | H21: 5071600 | I21: 6861375 | J21: 13560551 | K21: 19311175 | L21: 37569052 | M21: 28568220 | N21: 13218825 | O21: 16360500 | P21: =SUM(D21:O21) -> 184677874
A22: 2020 | B22: 2003.03.01 | C22: =_xlfn.XLOOKUP(B22, 'Revenue Codes'!$A$2:$A$99, 'Revenue Codes'!$B$2:$B$99, "") -> Fine & Forfeits | D22: -10714746 | E22: 87482592 | F22: 23030550 | G22: -22977704 | H22: 18883062 | I22: 33851159 | J22: 114936870 | K22: 1466640576 | L22: 8.3880759e+08 | M22: 184350837 | N22: 124523863 | O22: 30404000 | P22: =SUM(D22:O22) -> 2.8892186e+09
A23: 2020 | B23: 2003.02.99 | C23: =_xlfn.XLOOKUP(B23, 'Revenue Codes'!$A$2:$A$99, 'Revenue Codes'!$B$2:$B$99, "") -> Sundris & Others | D23: 17456948 | E23: 16831155 | F23: 10440846 | G23: 25295874 | H23: 9390457 | I23: 26282017 | J23: 19570836 | K23: 20575968 | L23: 20344612 | M23: 11744701 | N23: 22728309 | O23: 22390648 | P23: =SUM(D23:O23) -> 223052371
A24: 2020 | B24: 2003.99.00 | C24: =_xlfn.XLOOKUP(B24, 'Revenue Codes'!$A$2:$A$99, 'Revenue Codes'!$B$2:$B$99, "") -> Other Receipts | D24: 14062837 | E24: 12854432 | F24: 13311849 | G24: 4822648 | H24: 4237713 | I24: 7148808 | J24: 5676335 | K24: 5428661 | L24: 7457403 | M24: 7832955 | N24: 7317954 | O24: 17347376 | P24: =SUM(D24:O24) -> 107498971
A25: 2021 | B25: 1001.01.00 | C25: =_xlfn.XLOOKUP(B25, 'Revenue Codes'!$A$2:$A$99, 'Revenue Codes'!$B$2:$B$99, "") -> Import Duty | D25: 1.0060091e+10 | E25: 8.2192255e+09 | F25: 9.5607719e+09 | G25: 3.8040158e+09 | H25: 4.4246346e+09 | I25: 4.7259242e+09 | J25: 1.5572759e+10 | K25: 4.5248436e+09 | L25: -9.0799526e+09 | M25: 3680543867 | N25: 3.6377782e+09 | O25: 5.2086837e+09 | P25: =SUM(D25:O25) -> 6.4339318e+10
A26: 2021 | B26: 1001.02.00 | C26: =_xlfn.XLOOKUP(B26, 'Revenue Codes'!$A$2:$A$99, 'Revenue Codes'!$B$2:$B$99, "") -> Export Duty | D26: 2579082 | E26: 5945931 | F26: 13019171 | G26: 3016285 | H26: 3776831 | I26: 3450473 | J26: 2774288 | K26: 2133936 | L26: 1859767 | M26: 3272925 | N26: 2938189.1 | O26: 2655141 | P26: =SUM(D26:O26) -> 47422019
A27: 2021 | B27: 1001.04.00 | C27: =_xlfn.XLOOKUP(B27, 'Revenue Codes'!$A$2:$A$99, 'Revenue Codes'!$B$2:$B$99, "") -> PAL | D27: 11347077683 | E27: 11305090020 | F27: 14259918777 | G27: 16902272138 | H27: 12577980342 | I27: 1.3115297e+10 | J27: 2.3488919e+08 | K27: 1.2290648e+10 | L27: 2.2101465e+10 | M27: 1.1425529e+10 | N27: 1.2706991e+10 | O27: 1.585809e+10 | P27: =SUM(D27:O27) -> 1.5412525e+11
A28: 2021 | B28: 1001.05.00 | C28: =_xlfn.XLOOKUP(B28, 'Revenue Codes'!$A$2:$A$99, 'Revenue Codes'!$B$2:$B$99, "") -> Cess Levy | E28: 570514 | F28: 2390420 | G28: -2960934 | P28: =SUM(D28:O28) -> 0
A29: 2021 | B29: 1001.05.01 | C29: =_xlfn.XLOOKUP(B29, 'Revenue Codes'!$A$2:$A$99, 'Revenue Codes'!$B$2:$B$99, "") -> Cess (Import) | D29: 5595225410 | E29: 6428597557 | F29: 6948979373 | G29: 7082274768 | H29: 5669275688 | I29: 6.5441158e+09 | J29: 5.9589179e+09 | K29: 5.2491242e+09 | L29: 5.0441933e+09 | M29: 5.3646386e+09 | N29: 6.1793059e+09 | O29: 7255564876 | P29: =SUM(D29:O29) -> 7.3320213e+10
A30: 2021 | B30: 1001.05.02 | C30: =_xlfn.XLOOKUP(B30, 'Revenue Codes'!$A$2:$A$99, 'Revenue Codes'!$B$2:$B$99, "") -> Cess (Export) | D30: 115466623 | E30: 154486610 | F30: 240069407 | G30: 200854802 | H30: 276456834 | I30: 225489295 | J30: 205535276 | K30: 338795592 | L30: 116786158 | M30: -108734173 | N30: 208102609 | O30: 249976629 | P30: =SUM(D30:O30) -> 2223285662
A31: 2021 | B31: 1001.06.00 | C31: =_xlfn.XLOOKUP(B31, 'Revenue Codes'!$A$2:$A$99, 'Revenue Codes'!$B$2:$B$99, "") -> Motor Vehicle (Conc.) Levy | P31: =SUM(D31:O31) -> 0
A32: 2021 | B32: 1001.08.00 | C32: =_xlfn.XLOOKUP(B32, 'Revenue Codes'!$A$2:$A$99, 'Revenue Codes'!$B$2:$B$99, "") -> SCL | D32: 5758218040 | E32: 4454940367 | F32: 5958205721 | G32: 4329117098 | H32: 3930159232 | I32: 3979297951 | J32: 5.374773e+09 | K32: 4050553476 | L32: 4249166867 | M32: 3753900700 | N32: 5336497115 | O32: 4653043396 | P32: =SUM(D32:O32) -> 5.5827873e+10
A33: 2021 | B33: 1003.01.00 | C33: =_xlfn.XLOOKUP(B33, 'Revenue Codes'!$A$2:$A$99, 'Revenue Codes'!$B$2:$B$99, "") -> LXT | E33: 347141385 | F33: 619696 | I33: 46229322 | J33: 0 | K33: 0 | L33: 128214445 | M33: 261751350 | N33: - | O33: -130453288 | P33: =SUM(D33:O33) -> 653502910
A34: 2021 | B34: 1002.01.04 | C34: =_xlfn.XLOOKUP(B34, 'Revenue Codes'!$A$2:$A$99, 'Revenue Codes'!$B$2:$B$99, "") -> VAT | D34: 9263091587 | E34: 8658405592 | F34: 10861520571 | G34: 10624156667 | H34: 10696166888 | I34: 11243169555 | J34: 1.0141067e+10 | K34: 9.2450921e+09 | L34: 9651623591 | M34: 10335028410 | N34: 10380248034 | O34: 1.1623553e+10 | P34: =SUM(D34:O34) -> 1.2272312e+11
A35: 2021 | B35: 1002.05.00 | C35: =_xlfn.XLOOKUP(B35, 'Revenue Codes'!$A$2:$A$99, 'Revenue Codes'!$B$2:$B$99, "") -> Excise (Spec. Prov.) Levy | P35: =SUM(D35:O35) -> 0
A36: 2021 | B36: 1002.05.01 | C36: =_xlfn.XLOOKUP(B36, 'Revenue Codes'!$A$2:$A$99, 'Revenue Codes'!$B$2:$B$99, "") -> Cigarette | D36: 3762950740 | E36: 6743799800 | F36: 7886301200 | G36: 9208929100 | H36: 9295915800 | I36: 5555444600 | J36: 5233077300 | K36: 7509640000 | L36: 7105069400 | M36: 6767520400 | N36: 12406569100 | O36: 7063623648 | P36: =SUM(D36:O36) -> 88538841088
A37: 2021 | B37: 1002.05.02 | C37: =_xlfn.XLOOKUP(B37, 'Revenue Codes'!$A$2:$A$99, 'Revenue Codes'!$B$2:$B$99, "") -> Liquor | O37: - | P37: =SUM(D37:O37) -> 0
A38: 2021 | B38: 1002.05.03 | C38: =_xlfn.XLOOKUP(B38, 'Revenue Codes'!$A$2:$A$99, 'Revenue Codes'!$B$2:$B$99, "") -> Petroleum Products | D38: 1389275895 | E38: 5788965619 | F38: 7902980851 | G38: 5571406988 | H38: 5636228905 | I38: 1.153928e+09 | J38: 3.309034e+09 | K38: 6.7340692e+09 | L38: 2.1303742e+09 | M38: 4.4388389e+09 | N38: 5.8027016e+09 | O38: 5.4813486e+09 | P38: =SUM(D38:O38) -> 5.5339153e+10
A39: 2021 | B39: 1002.05.04 | C39: =_xlfn.XLOOKUP(B39, 'Revenue Codes'!$A$2:$A$99, 'Revenue Codes'!$B$2:$B$99, "") -> Motor Vehicles | D39: 4984488863 | E39: 1816381558 | F39: 1029316874 | G39: 90823666 | H39: 586936467 | I39: 2052451929 | J39: 524886543 | K39: 499525573 | L39: 1640593021 | M39: 615333668 | N39: 662911331 | O39: 3609033687 | P39: =SUM(D39:O39) -> 18112683180
A40: 2021 | B40: 1002.05.99 | C40: =_xlfn.XLOOKUP(B40, 'Revenue Codes'!$A$2:$A$99, 'Revenue Codes'!$B$2:$B$99, "") -> Excise (Other) | D40: 519728232 | E40: 580557990 | F40: 397187965 | G40: 1167300906 | H40: 342164159 | I40: 258238845 | J40: 7.8627411e+08 | K40: 465725514 | L40: 46483920 | M40: 1.1787554e+09 | N40: 191590101 | O40: 2.995887e+08 | P40: =SUM(D40:O40) -> 6.2335959e+09
...

Sheet Estimated Revenue
A1: Year | B1: Revenue Code | C1: Description | D1: January | E1: February | F1: March | G1: April | H1: May | I1: June | J1: July | K1: August | L1: September | M1: October | N1: November | O1: December | P1: Total | S1: Instructions
A2: 2022 | B2: 1001.01.00 | C2: =_xlfn.XLOOKUP(B2, 'Revenue Codes'!$A$2:$A$99, 'Revenue Codes'!$B$2:$B$99, "") -> Import Duty | D2: 3241000 | E2: 3124000 | F2: 3112000 | G2: 3158000 | H2: 3237000 | I2: 3339000 | J2: 3455000 | K2: 3582000 | L2: 3717000 | M2: 3860000 | N2: 4009000 | O2: 4165000 | P2: 41999000 | S2: 1) Revenue Code description appears automatically when code is entered. If code does not appear, add a new Revenue Code in the relevant Excel Sheet. 2) Fields automatically turns red if negative values are entered. Check and verify if those values are correct. 3) Enter all values in exact figures LKR '000 (Hundred Thousand's). Please maintain this standard 4) Values entered in this shared Excel automatically updates the Revenue Dashboard. If any errors in the dashboard is noticed, check values in this Excel Sheet.
A3: 2022 | B3: 1001.02.00 | C3: =_xlfn.XLOOKUP(B3, 'Revenue Codes'!$A$2:$A$99, 'Revenue Codes'!$B$2:$B$99, "") -> Export Duty | D3: 2000 | E3: 2000 | F3: 3000 | G3: 2000 | H3: 2000 | I3: 3000 | J3: 2000 | K3: 3000 | L3: 2000 | M3: 3000 | N3: 3000 | O3: 4000 | P3: 31000
A4: 2022 | B4: 1001.04.00 | C4: =_xlfn.XLOOKUP(B4, 'Revenue Codes'!$A$2:$A$99, 'Revenue Codes'!$B$2:$B$99, "") -> PAL | D4: 13341000 | E4: 12695000 | F4: 13556000 | G4: 13747000 | H4: 14267000 | I4: 14654000 | J4: 15122000 | K4: 15571000 | L4: 16050000 | M4: 15491000 | N4: 15995000 | O4: 16513000 | P4: 177002000
A5: 2022 | B5: 1001.05.01 | C5: =_xlfn.XLOOKUP(B5, 'Revenue Codes'!$A$2:$A$99, 'Revenue Codes'!$B$2:$B$99, "") -> Cess (Import) | D5: 5421000 | E5: 5330000 | F5: 5575000 | G5: 5173000 | H5: 5105000 | I5: 5892000 | J5: 5756000 | K5: 5633000 | L5: 5522000 | M5: 5421000 | N5: 5529000 | O5: 5643000 | P5: 66000000
A6: 2022 | B6: 1001.05.02 | C6: =_xlfn.XLOOKUP(B6, 'Revenue Codes'!$A$2:$A$99, 'Revenue Codes'!$B$2:$B$99, "") -> Cess (Export) | D6: 162000 | E6: 169000 | F6: 170000 | G6: 169000 | H6: 169000 | I6: 168000 | J6: 167000 | K6: 167000 | L6: 166000 | M6: 165000 | N6: 164000 | O6: 164000 | P6: 2000000
A7: 2022 | B7: 1001.08.00 | C7: =_xlfn.XLOOKUP(B7, 'Revenue Codes'!$A$2:$A$99, 'Revenue Codes'!$B$2:$B$99, "") -> SCL | D7: 2883000 | E7: 2948000 | F7: 2963000 | G7: 2960000 | H7: 2951000 | I7: 2939000 | J7: 2926000 | K7: 2913000 | L7: 2899000 | M7: 2886000 | N7: 2873000 | O7: 2860000 | P7: 35001000
A8: 2022 | B8: 1002.01.04 | C8: =_xlfn.XLOOKUP(B8, 'Revenue Codes'!$A$2:$A$99, 'Revenue Codes'!$B$2:$B$99, "") -> VAT | D8: 16482000 | E8: 15261000 | F8: 16800000 | G8: 16435000 | H8: 17426000 | I8: 17489000 | J8: 18223000 | K8: 18508000 | L8: 19129000 | M8: 19536000 | N8: 20115000 | O8: 20596000 | P8: 216000000
A9: 2022 | B9: 1002.05.01 | C9: =_xlfn.XLOOKUP(B9, 'Revenue Codes'!$A$2:$A$99, 'Revenue Codes'!$B$2:$B$99, "") -> Cigarette | D9: 7567000 | E9: 8834000 | F9: 9068000 | G9: 9150000 | H9: 9212000 | I9: 9272000 | J9: 9331000 | K9: 9392000 | L9: 9452000 | M9: 9513000 | N9: 9574000 | O9: 9636000 | P9: 110001000
A10: 2022 | B10: 1002.05.03 | C10: =_xlfn.XLOOKUP(B10, 'Revenue Codes'!$A$2:$A$99, 'Revenue Codes'!$B$2:$B$99, "") -> Petroleum Products | D10: 2896000 | E10: 5691000 | F10: 5046000 | G10: 5008000 | H10: 4892000 | I10: 4790000 | J10: 4688000 | K10: 4588000 | L10: 4491000 | M10: 4396000 | N10: 4302000 | O10: 4211000 | P10: 54999000
A11: 2022 | B11: 1002.05.04 | C11: =_xlfn.XLOOKUP(B11, 'Revenue Codes'!$A$2:$A$99, 'Revenue Codes'!$B$2:$B$99, "") -> Motor Vehicles | D11: 1480000 | E11: 2319000 | F11: 1061000 | G11: 1480000 | H11: 1110000 | I11: 1529000 | J11: 1258000 | K11: 1283000 | L11: 1334000 | M11: 1568000 | N11: 1727000 | O11: 1850000 | P11: 17999000
A12: 2022 | B12: 1002.05.99 | C12: =_xlfn.XLOOKUP(B12, 'Revenue Codes'!$A$2:$A$99, 'Revenue Codes'!$B$2:$B$99, "") -> Excise (Other) | D12: 491000 | E12: 491000 | F12: 491000 | G12: 491000 | H12: 491000 | I12: 491000 | J12: 438000 | K12: 511000 | L12: 483000 | M12: 494000 | N12: 490000 | O12: 639000 | P12: 6001000
A13: 2022 | B13: 1003.07.10 | C13: =_xlfn.XLOOKUP(B13, 'Revenue Codes'!$A$2:$A$99, 'Revenue Codes'!$B$2:$B$99, "") -> VEL | D13: 12000 | E13: 11000 | F13: 10000 | G13: 10000 | H13: 9000 | I13: 9000 | J13: 9000 | K13: 8000 | L13: 8000 | M13: 7000 | N13: 7000 | O13: 7000 | P13: 107000
A14: 2022 | B14: 1003.01.00 | C14: =_xlfn.XLOOKUP(B14, 'Revenue Codes'!$A$2:$A$99, 'Revenue Codes'!$B$2:$B$99, "") -> LXT | D14: 49000 | E14: 37000 | F14: 49000 | G14: 37000 | H14: 59000 | I14: 70000 | J14: 86000 | K14: 98000 | L14: 112000 | M14: 132000 | N14: 141000 | O14: 132000 | P14: 1002000
A15: 2022 | B15: 1002.12.03 | C15: =_xlfn.XLOOKUP(B15, 'Revenue Codes'!$A$2:$A$99, 'Revenue Codes'!$B$2:$B$99, "") -> NBT
A16: 2022 | B16: 1002.16.00 | C16: =_xlfn.XLOOKUP(B16, 'Revenue Codes'!$A$2:$A$99, 'Revenue Codes'!$B$2:$B$99, "") -> SSCL | M16: 2500000 | N16: 2500000 | O16: 2500000 | P16: 7500000
A17: 2022 | B17: 1004.04.02 | C17: =_xlfn.XLOOKUP(B17, 'Revenue Codes'!$A$2:$A$99, 'Revenue Codes'!$B$2:$B$99, "") -> ESC
A18: 2022 | B18: 2003.02.17 | C18: =_xlfn.XLOOKUP(B18, 'Revenue Codes'!$A$2:$A$99, 'Revenue Codes'!$B$2:$B$99, "") -> Sales of Garment | D18: 8000 | E18: 13000 | F18: 13000 | G18: 13000 | H18: 13000 | I18: 13000 | J18: 13000 | K18: 13000 | L18: 13000 | M18: 13000 | N18: 13000 | O18: 13000 | P18: 151000
A19: 2022 | B19: 2003.03.01 | C19: =_xlfn.XLOOKUP(B19, 'Revenue Codes'!$A$2:$A$99, 'Revenue Codes'!$B$2:$B$99, "") -> Fine & Forfeits | D19: 82000 | E19: 178000 | F19: 181000 | G19: 178000 | H19: 181000 | I19: 179000 | J19: 180000 | K19: 179000 | L19: 180000 | M19: 179000 | N19: 180000 | O19: 179000 | P19: 2056000
A20: 2022 | B20: 2003.02.99 | C20: =_xlfn.XLOOKUP(B20, 'Revenue Codes'!$A$2:$A$99, 'Revenue Codes'!$B$2:$B$99, "") -> Sundris & Others | D20: 14000 | E20: 14000 | F20: 14000 | G20: 13000 | H20: 13000 | I20: 13000 | J20: 12000 | K20: 12000 | L20: 12000 | M20: 12000 | N20: 11000 | O20: 11000 | P20: 151000
A21: 2022 | B21: 2003.99.00 | C21: =_xlfn.XLOOKUP(B21, 'Revenue Codes'!$A$2:$A$99, 'Revenue Codes'!$B$2:$B$99, "") -> Other Receipts | D21: 15000 | E21: 16000 | F21: 16000 | G21: 16000 | H21: 17000 | I21: 17000 | J21: 17000 | K21: 17000 | L21: 17000 | M21: 17000 | N21: 17000 | O21: 17000 | P21: 199000
A22: 2024 | B22: 1001.01.00 | C22: =_xlfn.XLOOKUP(B22, 'Revenue Codes'!$A$2:$A$99, 'Revenue Codes'!$B$2:$B$99, "") -> Import Duty | D22: 8495000 | E22: 14960000 | F22: 11651000 | G22: 8578000 | H22: 12189000 | I22: 12655000 | J22: 7087000 | K22: 26869000 | L22: 15645000 | M22: 13640000 | N22: 22665000 | O22: 20566000 | P22: 175000000
A23: 2024 | B23: 1001.02.00 | C23: =_xlfn.XLOOKUP(B23, 'Revenue Codes'!$A$2:$A$99, 'Revenue Codes'!$B$2:$B$99, "") -> Export Duty | D23: 1000 | E23: 1000 | F23: 3000 | G23: 3000 | H23: 4000 | I23: 4000 | J23: 3000 | K23: 3000 | L23: 5000 | M23: 3000 | N23: 2000 | O23: 3000 | P23: 35000
A24: 2024 | B24: 1001.04.00 | C24: =_xlfn.XLOOKUP(B24, 'Revenue Codes'!$A$2:$A$99, 'Revenue Codes'!$B$2:$B$99, "") -> PAL | D24: 13731000 | E24: 19891000 | F24: 15831000 | G24: 11831000 | H24: 13407000 | I24: 13823000 | J24: 12918000 | K24: 12062000 | L24: 15045000 | M24: 15531000 | N24: 15902000 | O24: 15027000 | P24: 174999000
A25: 2024 | B25: 1001.05.01 | C25: =_xlfn.XLOOKUP(B25, 'Revenue Codes'!$A$2:$A$99, 'Revenue Codes'!$B$2:$B$99, "") -> Cess (Import) | D25: 7188000 | E25: 6036000 | F25: 3422000 | G25: 4916000 | H25: 6055000 | I25: 6132000 | J25: 5422000 | K25: 2862000 | L25: 6012000 | M25: 2862000 | N25: 3042000 | O25: 4051000 | P25: 58000000
A26: 2024 | B26: 1001.05.02 | C26: =_xlfn.XLOOKUP(B26, 'Revenue Codes'!$A$2:$A$99, 'Revenue Codes'!$B$2:$B$99, "") -> Cess (Export) | D26: 140000 | E26: 207000 | F26: 158000 | G26: 112000 | H26: 169000 | I26: 183000 | J26: 141000 | K26: 220000 | L26: 193000 | M26: 115000 | N26: 130000 | O26: 232000 | P26: 2000000
A27: 2024 | B27: 1001.08.00 | C27: =_xlfn.XLOOKUP(B27, 'Revenue Codes'!$A$2:$A$99, 'Revenue Codes'!$B$2:$B$99, "") -> SCL | D27: 6753000 | E27: 5215000 | F27: 12584000 | G27: 6652000 | H27: 9624000 | I27: 10237000 | J27: 10384000 | K27: 8943000 | L27: 9955000 | M27: 10446000 | N27: 2879000 | O27: 1329000 | P27: 95001000
A28: 2024 | B28: 1002.01.04 | C28: =_xlfn.XLOOKUP(B28, 'Revenue Codes'!$A$2:$A$99, 'Revenue Codes'!$B$2:$B$99, "") -> VAT | D28: 51795000 | E28: 45687000 | F28: 50758000 | G28: 44964000 | H28: 54219000 | I28: 51833000 | J28: 59099000 | K28: 56181000 | L28: 56431000 | M28: 59957000 | N28: 66244000 | O28: 62833000 | P28: 660001000
A29: 2024 | B29: 1002.16.03 | C29: =_xlfn.XLOOKUP(B29, 'Revenue Codes'!$A$2:$A$99, 'Revenue Codes'!$B$2:$B$99, "") -> SSL | D29: 5004000 | E29: 3835000 | F29: 4080000 | G29: 4036000 | H29: 6153000 | I29: 5852000 | J29: 4593000 | K29: 3790000 | L29: 4867000 | M29: 4486000 | N29: 4281000 | O29: 4023000 | P29: 55000000
... A41: 2024 | B41: 2003.99.00 | C41: =_xlfn.XLOOKUP(B41, 'Revenue Codes'!$A$2:$A$99, 'Revenue Codes'!$B$2:$B$99, "") -> Other Receipts | D41: 18000 | E41: 17000 | F41: 18000 | G41: 17000 | H41: 17000 | I41: 18000 | J41: 17000 | K41: 18000 | L41: 17000 | M41: 18000 | N41: 17000 | O41: 18000 | P41: 210000
A42: 2025 | B42: 1001.01.00 | C42: =_xlfn.XLOOKUP(B42, 'Revenue Codes'!$A$2:$A$99, 'Revenue Codes'!$B$2:$B$99, "") -> Import Duty | D42: 9577000 | E42: 10766000 | F42: 11611000 | G42: 17294953 | H42: 21925625 | I42: 22534924 | J42: 23753522 | K42: 23144223 | L42: 22534924 | M42: 24972120 | N42: 25581418 | O42: 26304292 | P42: =SUM(D42:O42) -> 240000001
A43: 2025 | B43: 1001.02.00 | C43: =_xlfn.XLOOKUP(B43, 'Revenue Codes'!$A$2:$A$99, 'Revenue Codes'!$B$2:$B$99, "") -> Export Duty | D43: 2000 | E43: 2000 | F43: 1000 | G43: 2245 | H43: 2845 | I43: 2925 | J43: 3083 | K43: 3004 | L43: 2925 | M43: 3241 | N43: 3320 | O43: 3414 | P43: =SUM(D43:O43) -> 32002
A44: 2025 | B44: 1001.04.00 | C44: =_xlfn.XLOOKUP(B44, 'Revenue Codes'!$A$2:$A$99, 'Revenue Codes'!$B$2:$B$99, "") -> PAL | D44: 12895000 | E44: 13031000 | F44: 15367000 | G44: 11996424 | H44: 15195044 | I44: 15615915 | J44: 16457657 | K44: 16036786 | L44: 15615915 | M44: 17299399 | N44: 17720269 | O44: 17769591 | P44: =SUM(D44:O44) -> 185000000
A45: 2025 | B45: 1001.05.01 | C45: =_xlfn.XLOOKUP(B45, 'Revenue Codes'!$A$2:$A$99, 'Revenue Codes'!$B$2:$B$99, "") -> Cess (Import) | D45: 7113000 | E45: 7404000 | F45: 6303000 | G45: 6399297 | H45: 8112795 | I45: 8338245 | J45: 8789143 | K45: 8563694 | L45: 8338245 | M45: 9240042 | N45: 9465491 | O45: 9733047 | P45: =SUM(D45:O45) -> 97799999
A46: 2025 | B46: 1001.05.02 | C46: =_xlfn.XLOOKUP(B46, 'Revenue Codes'!$A$2:$A$99, 'Revenue Codes'!$B$2:$B$99, "") -> Cess (Export) | D46: 101000 | E46: 86000 | F46: 101000 | G46: 158945 | H46: 201503 | I46: 207102 | J46: 218301 | K46: 212702 | L46: 207102 | M46: 229501 | N46: 235100 | O46: 241744 | P46: =SUM(D46:O46) -> 2200000
A47: 2025 | B47: 1001.08.00 | C47: =_xlfn.XLOOKUP(B47, 'Revenue Codes'!$A$2:$A$99, 'Revenue Codes'!$B$2:$B$99, "") -> SCL | D47: 19302000 | E47: 13129000 | F47: 15461000 | G47: 6493151 | H47: 8231673 | I47: 8460426 | J47: 8917932 | K47: 8689179 | L47: 8460426 | M47: 9375438 | N47: 9604068 | O47: 9875707 | P47: =SUM(D47:O47) -> 126000000
A48: 2025 | B48: 1002.01.04 | C48: =_xlfn.XLOOKUP(B48, 'Revenue Codes'!$A$2:$A$99, 'Revenue Codes'!$B$2:$B$99, "") -> VAT | D48: 53082000 | E48: 49041000 | F48: 50346000 | G48: 52998224 | H48: 67188236 | I48: 69055462 | J48: 72789703 | K48: 70922471 | L48: 69055462 | M48: 76523945 | N48: 78391064 | O48: 80606434 | P48: =SUM(D48:O48) -> 790000001
A49: 2025 | B49: 1002.16.03 | C49: =_xlfn.XLOOKUP(B49, 'Revenue Codes'!$A$2:$A$99, 'Revenue Codes'!$B$2:$B$99, "") -> SSL | D49: 5960000 | E49: 5412000 | F49: 4985000 | G49: 4791887 | H49: 6074901 | I49: 6243718 | J49: 6581239 | K49: 6412536 | L49: 6243718 | M49: 6918989 | N49: 7087806 | O49: 7288206 | P49: =SUM(D49:O49) -> 74000000
A50: 2025 | B50: 1002.05.01 | C50: =_xlfn.XLOOKUP(B50, 'Revenue Codes'!$A$2:$A$99, 'Revenue Codes'!$B$2:$B$99, "") -> Cigarette | D50: 11426000 | E50: 8631000 | F50: 6330000 | G50: 8613393 | H50: 10919603 | I50: 11222944 | J50: 11829949 | K50: 11526501 | L50: 11223052 | M50: 12436727 | N50: 12740295 | O50: 13100535 | P50: =SUM(D50:O50) -> 129999999
A51: 2025 | B51: 1002.05.03 | C51: =_xlfn.XLOOKUP(B51, 'Revenue Codes'!$A$2:$A$99, 'Revenue Codes'!$B$2:$B$99, "") -> Petroleum Products | D51: 15041000 | E51: 16526000 | F51: 16389000 | G51: 15133395 | H51: 19185317 | I51: 19718465 | J51: 20784760 | K51: 20251612 | L51: 19718465 | M51: 21851055 | N51: 22384202 | O51: 23016729 | P51: =SUM(D51:O51) -> 230000000
...

Sheet Daily Revenue
A1: Date | B1: Cash reveres | C1: Vat Refund | D1: BOC 7041607 | E1: BOC 7041608 | F1: DST 2026450 | G1: PB 9026645 | H1: PB 59025247 | I1: DST 30110432 | J1: Total | K1: Cumulative Total | L1: Daily Target | M1: Cumulative Target | N1: Percentage Achieved | R1: Instructions
A2: 43831 | R2: 1) Holidays should be entered in the Holidays sheet. Relevant days are automatically updated. 2) Enter all values in exact figures LKR (Not is millions, '000, billion etc.) 3) Values entered in this shared Excel automatically updates the Revenue Dashboard. If any errors in the dashboard is noticed, check values in this Excel Sheet.
A3: 43832
A4: 43833
A5: 43834
A6: 43835
A7: 43836
A8: 43837
A9: 43838
A10: 43839
A11: 43840
A12: 43841
A13: 43842
A14: 43843
... A1097: 44926
A1098: 44927 | D1098: - | E1098: - | F1098: - | G1098: 6694264 | H1098: - | I1098: 6694264 | J1098: 6694264 | M1098: -
A1099: 44928 | D1099: 1533584412 | E1099: - | F1099: 1533584412 | G1099: 90919983 | H1099: - | I1099: 90919983 | J1099: 1624504395 | M1099: 2406000000
A1100: 44929 | D1100: 1946200624 | F1100: 1946200624 | G1100: 98557515 | H1100: 8500000000 | I1100: 8598557515 | J1100: 10544758139 | M1100: 4809000000
A1101: 44930 | D1101: 2253347382 | F1101: 2253347382 | G1101: 79743668 | H1101: 51913400 | I1101: 131657068 | J1101: 2385004450 | M1101: 7217000000
A1102: 44931 | D1102: 4.0754921e+09 | F1102: 4.0754921e+09 | G1102: 87839191 | H1102: 100000000 | I1102: 187839191 | J1102: 4.2633313e+09 | M1102: 9723000000
A1103: 44932 | D1103: - | F1103: - | G1103: 5366963 | H1103: - | I1103: 5366963 | J1103: 5366963 | M1103: 9723000000
A1104: 44933 | D1104: - | F1104: - | G1104: 1100850 | H1104: - | I1104: 1100850 | J1104: 1100850 | M1104: 9723000000
A1105: 44934 | D1105: - | F1105: - | G1105: - | I1105: - | J1105: - | M1105: 9723000000
A1106: 44935 | D1106: 2.5221205e+09 | F1106: 2.5221205e+09 | G1106: 107455057 | I1106: 107455057 | J1106: 2.6295756e+09 | M1106: 11994000000
A1107: 44936 | D1107: 2082499521 | F1107: 2082499521 | G1107: 202826142 | I1107: 202826142 | J1107: 2285325663 | M1107: 14424000000
A1108: 44937 | D1108: 2891698773 | E1108: 803399 | F1108: 2892502172 | G1108: 140158352 | I1108: 140158352 | J1108: 3032660524 | M1108: 16866000000
A1109: 44938 | D1109: 2.1391204e+09 | E1109: 4834409 | F1109: 2.1439548e+09 | G1109: 76039743 | I1109: 76039743 | J1109: 2.2199946e+09 | M1109: 19286000000
A1110: 44939 | D1110: 1801734336 | F1110: 1801734336 | G1110: 167004014 | H1110: 100000000 | I1110: 267004014 | J1110: 2068738350 | M1110: 33240000000
A1111: 44940 | F1111: - | G1111: 2200 | I1111: 2200 | J1111: 2200 | M1111: 33240000000
A1112: 44941 | F1112: - | I1112: - | J1112: - | M1112: 33240000000
A1113: 44942 | F1113: - | G1113: 4028274 | I1113: 4028274 | J1113: 4028274 | M1113: 35645000000
A1114: 44943 | D1114: 2593842758 | E1114: 278648 | F1114: 2594121406 | G1114: 99783072 | I1114: 99783072 | J1114: 2693904478 | M1114: 38046000000
A1115: 44944 | D1115: 2751051294 | E1115: 251188.5 | F1115: 2.7513025e+09 | G1115: 143366058 | I1115: 143366058 | J1115: 2.8946685e+09 | M1115: 40452000000
A1116: 44945 | D1116: 2162300666 | E1116: 6134828 | F1116: 2168435494 | G1116: 102718771 | I1116: 102718771 | J1116: 2271154265 | M1116: 42860000000
A1117: 44946 | D1117: 1777717383 | E1117: 6670640 | F1117: 1784388023 | G1117: 107140628 | H1117: 100000000 | I1117: 207140628 | J1117: 1991528651 | M1117: 45373000000
A1118: 44947 | F1118: - | G1118: 2184459 | H1118: - | I1118: 2184459 | J1118: 2184459 | M1118: 45373000000
A1119: 44948 | F1119: - | G1119: - | H1119: - | I1119: - | J1119: - | M1119: 45373000000
A1120: 44949 | D1120: 2.9025835e+09 | E1120: - | F1120: 2.9025835e+09 | G1120: 56770087 | H1120: - | I1120: 56770087 | J1120: 2.9593536e+09 | M1120: 47781000000
A1121: 44950 | D1121: 2327667728 | E1121: - | F1121: 2327667728 | G1121: 112994445 | H1121: - | I1121: 112994445 | J1121: 2440662173 | M1121: 50187000000
A1122: 44951 | D1122: 3496762111 | E1122: 2432215.5 | F1122: 3.4991943e+09 | G1122: 162361825 | H1122: - | I1122: 162361825 | J1122: 3.6615562e+09 | M1122: 52590000000
...

Sheet Revenue Codes
A1: Revenue Code | B1: Description | F1: Instructions
A2: 1001.01.00 | B2: Import Duty | F2: 1) Include all revenue items under each revenue code ensuring completeness and accuracy 2) Check if suitable revenue code exists before creating new ones. 3) New revenue codes can be added to this table from the next available line. Always remember to enter the revenue code in the usual format with a suitable short description.
A3: 1001.02.00 | B3: Export Duty
A4: 1001.04.00 | B4: PAL
A5: 1001.05.01 | B5: Cess (Import)
A6: 1001.05.02 | B6: Cess (Export)
A7: 1001.08.00 | B7: SCL
A8: 1002.01.04 | B8: VAT
A9: 1002.16.03 | B9: SSL
A10: 1002.05.01 | B10: Cigarette
A11: 1002.05.03 | B11: Petroleum Products
A12: 1002.05.04 | B12: Motor Vehicles
A13: 1002.05.99 | B13: Excise (Other)
A14: 1003.07.10 | B14: VEL
... A29: 1001.03.00 | B29: IECD License Fee

Sheet Holidays
A1: Date | B1: Day | C1: Holiday Name | D1: Holiday Type | H1: Instructions
A2: 43840 | B2: Friday | C2: Duruthu Full Moon Poya Day | D2: Public & Bank | H2: 1) Please update this table to automatically highlight the holidays. 2) Any holidays not noted in the table can be added at the end. Order of table does not have an impact on functionality. 3) This table helps understands daily revenue collections. It does not have a bearing on the functionality of the Excel
A3: 43845 | B3: Wednesday | C3: Tamil Thai Pongal Day | D3: Public, Bank & Mercantile
A4: 43865 | B4: Tuesday | C4: National Day | D4: Public, Bank & Mercantile
A5: 43869 | B5: Saturday | C5: Navam Full Moon Poya Day | D5: Public & Bank
A6: 43882 | B6: Friday | C6: Mahasivarathri Day | D6: Public & Bank
A7: 43899 | B7: Monday | C7: Medin Full Moon Poya Day | D7: Public & Bank
A8: 43928 | B8: Tuesday | C8: Bak Full Moon Poya Day | D8: Public & Bank
A9: 43931 | B9: Friday | C9: Good Friday | D9: Public & Bank
A10: 43933 | B10: Sunday | C10: Day prior to Sinhala & Tamil New Year Day | D10: Public, Bank & Mercantile
A11: 43934 | B11: Monday | C11: Sinhala & Tamil New Year Day | D11: Public, Bank & Mercantile
A12: 43935 | B12: Tuesday | C12: Special Bank Holiday | D12: Bank
A13: 43952 | B13: Friday | C13: May Day (Labour Day) | D13: Public, Bank & Mercantile
A14: 43958 | B14: Thursday | C14: Vesak Full Moon Poya Day | D14: Public & Bank
... A187: 46381 | B187: Friday | C187: Christmas Day | D187: Public, Bank & Mercantile
